<?xml version="1.0"?>
<robot name="car_model">

  <gazebo>
    <static>False</static>
  </gazebo>

  <material name="grey">
    <color rgba="0.2 0.2 0.2 0.7"/>
  </material>

  <material name="black">
    <color rgba="0 0 0 0.7"/>
  </material>

  <material name="yellow">
    <color rgba="1 1 0 0.7"/>
  </material>



  <link name="base_footprint">

    <inertial>
      <origin xyz="0 0 0"/>
      <mass value="1.0"/>
      <inertia ixx="1" ixy="0.0" ixz="0.0" iyy="1" iyz="0.0" izz="1"/>
    </inertial>

    <visual>
      <geometry>
        <box size="0.001 0.001 0.001"/>
      </geometry>
      <origin xyz="0 0 0" rpy="0 0 0"/>
    </visual>


  </link>

  <joint name="joint1" type="fixed">
    <parent link="base_footprint"/>
    <child link="base_link"/>
    <origin xyz="0 0 0.5" rpy="0 0 0"/>
  </joint>

  <link name="base_link">

    <inertial>
      <origin xyz="0 0 0"/>
      <mass value="212"/>
      <inertia ixx="1.4133" ixy="0.0" ixz="0.0" iyy="159.7" iyz="0.0" izz="159.7"/>
    </inertial>

    <visual>
      <geometry>
        <box size="2.4 1.2 0.2"/>
      </geometry>
      <origin rpy="0 0 0" xyz="0 0 0"/>
      <material name="yellow"/>
    </visual>

    <collision>
      <geometry>
        <box size="2.4 1.2 0.2"/>
      </geometry>
      <origin rpy="0 0 0" xyz="0 0 0"/>
    </collision>

  </link>

  <gazebo reference="base_link">
    <material>Gazebo/Yellow</material>
  </gazebo>

  <joint name="right_rear_wheel_joint" type="continuous">
    <parent link="base_link"/>
    <child link="right_rear_wheel"/>
    <origin xyz="-1.1 0.8 -0.3" rpy="0 0 0"/>
    <axis xyz="0 1 0"/>
  </joint>


  <link name="right_rear_wheel">

    <inertial>
      <origin xyz="0 0 0"/>
      <mass value="3.0"/>
      <inertia ixx="0.0525" ixy="0.0" ixz="0.0" iyy="0.0525" iyz="0.0" izz="0.06"/>
    </inertial>

    <visual>
      <geometry>
        <cylinder radius="0.2" length="0.2"/>
      </geometry>
      <origin xyz="0 0 0" rpy="1.57 0 0"/>
      <material name="black"/>
    </visual>

    <collision>
      <geometry>
        <cylinder radius="0.2" length="0.2"/>
      </geometry>
      <origin xyz="0 0 0" rpy="1.57 0 0"/>
    </collision>
  </link>


  <joint name="left_rear_wheel_joint" type="continuous">
    <parent link="base_link"/>
    <child link="left_rear_wheel"/>
    <origin xyz="-1.1 -0.8 -0.3" rpy="0 0 0"/>
    <axis xyz="0 1 0"/>
  </joint>


  <link name="left_rear_wheel">

    <inertial>
      <origin xyz="0 0 0"/>
      <mass value="3.0"/>
      <inertia ixx="0.0525" ixy="0.0" ixz="0.0" iyy="0.0525" iyz="0.0" izz="0.06"/>
    </inertial>

    <visual>
      <geometry>
        <cylinder radius="0.2" length="0.2"/>
      </geometry>
      <origin xyz="0 0 0" rpy="1.57 0 0"/>
      <material name="black"/>
    </visual>

    <collision>
      <geometry>
        <cylinder radius="0.2" length="0.2"/>
      </geometry>
      <origin xyz="0 0 0" rpy="1.57 0 0"/>
    </collision>
  </link>




  <transmission name="rear_wheel_trans">
    <type>transmission_interface/SimpleTransmission</type>
    <joint name="right_rear_wheel_joint">
      <hardwareInterface>hardware_interface/EffortJointInterface</hardwareInterface>

    </joint>
    <actuator name="rear_wheel_motor">
      <mechanicalReduction>50</mechanicalReduction>
      <hardwareInterface>hardware_interface/EffortJointInterface</hardwareInterface>
      <mechanicalReduction>1</mechanicalReduction>
    </actuator>
  </transmission>

  <transmission name="rear_wheel_trans">
    <type>transmission_interface/SimpleTransmission</type>
    <joint name="left_rear_wheel_joint">
      <hardwareInterface>hardware_interface/EffortJointInterface</hardwareInterface>

    </joint>
    <actuator name="rear_wheel_motor">
      <mechanicalReduction>50</mechanicalReduction>
      <hardwareInterface>hardware_interface/EffortJointInterface</hardwareInterface>
      <mechanicalReduction>1</mechanicalReduction>
    </actuator>
  </transmission>

  <gazebo reference="rear_wheel">
    <mu1 value="0.2"/>
    <mu2 value="0.2"/>
    <kp  value="10000000.0" />
    <kd  value="1.0" />
    <fdir1 value="1 0 0"/>
    <material>Gazebo/Black</material>
  </gazebo>


  <joint name="right_steer_joint" type="revolute">
    <parent link="base_link"/>
    <child link="right_steer"/>
    <origin xyz="1.2 0.8 -0.25" rpy="0 0 0"/>
    <limit effort="10" velocity="3" upper="1" lower="-1"/>
    <axis xyz="0 0 1"/>
  </joint>

<link name="right_steer">

    <inertial>
      <origin xyz="0 0 0"/>
      <mass value="1.0"/>
      <inertia ixx="0.0525" ixy="0.0" ixz="0.0" iyy="0.0525" iyz="0.0" izz="0.06"/>
    </inertial>

    <visual>
      <geometry>
        <cylinder radius="0.02" length="0.02"/>
      </geometry>
      <origin xyz="0 0 0" rpy="1.57 0 0"/>
      <material name="black"/>
    </visual>

    <collision>
      <geometry>
        <cylinder radius="0.02" length="0.02"/>
      </geometry>
      <origin xyz="0 0 0" rpy="1.57 0 0"/>
    </collision>
  </link>

  <link name="right_front_wheel">

    <inertial>
      <origin xyz="0 0 0"/>
      <mass value="3.0"/>
      <inertia ixx="0.0525" ixy="0.0" ixz="0.0" iyy="0.0525" iyz="0.0" izz="0.06"/>
    </inertial>

    <visual>
      <geometry>
        <cylinder radius="0.2" length="0.2"/>
      </geometry>
      <origin xyz="0 0 0" rpy="1.57 0 0"/>
      <material name="black"/>
    </visual>

    <collision>
      <geometry>
        <cylinder radius="0.2" length="0.2"/>
      </geometry>
      <origin xyz="0 0 0" rpy="1.57 0 0"/>
    </collision>
  </link>

  <joint name="right_front_wheel_joint" type="continuous">
    <parent link="right_steer"/>
    <child link="right_front_wheel"/>
    <origin xyz="0 0.1 -0.1" rpy="0 0 0"/>
    <limit effort="10" velocity="3"/>
    <axis xyz="0 1 0"/>
  </joint>

<joint name="left_steer_joint" type="revolute">
    <parent link="base_link"/>
    <child link="left_steer"/>
    <origin xyz="1.2 -0.8 -0.25" rpy="0 0 0"/>
    <limit effort="10" velocity="3" upper="1" lower="-1"/>
    <axis xyz="0 0 1"/>
  </joint>

<link name="left_steer">

    <inertial>
      <origin xyz="0 0 0"/>
      <mass value="1.0"/>
      <inertia ixx="0.0525" ixy="0.0" ixz="0.0" iyy="0.0525" iyz="0.0" izz="0.06"/>
    </inertial>

    <visual>
      <geometry>
        <cylinder radius="0.02" length="0.02"/>
      </geometry>
      <origin xyz="0 0 0" rpy="1.57 0 0"/>
      <material name="black"/>
    </visual>

    <collision>
      <geometry>
        <cylinder radius="0.02" length="0.02"/>
      </geometry>
      <origin xyz="0 0 0" rpy="1.57 0 0"/>
    </collision>
  </link>

  <link name="left_front_wheel">

    <inertial>
      <origin xyz="0 0 0"/>
      <mass value="3.0"/>
      <inertia ixx="0.0525" ixy="0.0" ixz="0.0" iyy="0.0525" iyz="0.0" izz="0.06"/>
    </inertial>

    <visual>
      <geometry>
        <cylinder radius="0.2" length="0.2"/>
      </geometry>
      <origin xyz="0 0 0" rpy="1.57 0 0"/>
      <material name="black"/>
    </visual>

    <collision>
      <geometry>
        <cylinder radius="0.2" length="0.2"/>
      </geometry>
      <origin xyz="0 0 0" rpy="1.57 0 0"/>
    </collision>
  </link>

  <joint name="left_front_wheel_joint" type="continuous">
    <parent link="left_steer"/>
    <child link="left_front_wheel"/>
    <origin xyz="0 0.1 -0.1" rpy="0 0 0"/>
    <limit effort="10" velocity="3"/>
    <axis xyz="0 1 0"/>
  </joint>
  <transmission name="right_front_wheel_trans">
    <type>transmission_interface/SimpleTransmission</type>
    <joint name="right_steer_joint">
      <hardwareInterface>hardware_interface/EffortJointInterface</hardwareInterface>
    </joint>
    <actuator name="front_wheel_motor">
      <mechanicalReduction>50</mechanicalReduction>
      <hardwareInterface>hardware_interface/EffortJointInterface</hardwareInterface>
      <mechanicalReduction>1</mechanicalReduction>
    </actuator>
  </transmission>

  <transmission name="left_front_wheel_trans">
    <type>transmission_interface/SimpleTransmission</type>
    <joint name="left_steer_joint">
      <hardwareInterface>hardware_interface/EffortJointInterface</hardwareInterface>
    </joint>
    <actuator name="front_wheel_motor">
      <mechanicalReduction>50</mechanicalReduction>
      <hardwareInterface>hardware_interface/EffortJointInterface</hardwareInterface>
      <mechanicalReduction>1</mechanicalReduction>
    </actuator>
  </transmission>

  <gazebo reference="front_wheel">
    <mu1 value="0.2"/>
    <mu2 value="0.2"/>
    <kp  value="10000000.0" />
    <kd  value="1.0" />
    <fdir1 value="1 0 0"/>
    <material>Gazebo/Black</material>
  </gazebo>

  <gazebo>
    <plugin name="gazebo_ros_control" filename="libgazebo_ros_control.so">
      <robotNamespace>/car_model</robotNamespace>
      <robotSimType>gazebo_ros_control/DefaultRobotHWSim</robotSimType>
    </plugin>
  </gazebo>

<link name="hokuyo_link">
    <visual>
      <origin rpy="0 0 0" xyz="0 0 0"/>
      <geometry>
        <box size="0.05 0.05 0.05"/>
      </geometry>
      <material name="Blue"/>
    </visual>
  </link>
  <joint name="hokuyo_joint" type="fixed">
    <origin rpy="0 0 0" xyz="1.5 0 -0.5"/>
    <parent link="base_link"/>
    <child link="hokuyo_link"/>
  </joint>
  <gazebo reference="hokuyo_link">
    <material>Gazebo/Blue</material>
    <turnGravityOff>false</turnGravityOff>
    <sensor name="head_hokuyo_sensor" type="ray">
      <pose>0.025 0 0 0 0 0</pose>
      <visualize>true</visualize>
      <update_rate>40</update_rate>
      <ray>
        <scan>
          <horizontal>
            <samples>720</samples>
            <resolution>1</resolution>
            <min_angle>-1.570796</min_angle>
            <max_angle>1.570796</max_angle>
          </horizontal>
        </scan>
        <range>
          <min>0.10</min>
          <max>10.0</max>
          <resolution>0.001</resolution>
        </range>
      </ray>
      <plugin filename="libgazebo_ros_laser.so" name="gazebo_ros_head_hokuyo_controller">
        <topicName>/scan</topicName>
        <frameName>hokuyo_link</frameName>
      </plugin>
    </sensor>
  </gazebo>
  <!--link name="laser">
	<visual>
      	  <geometry>
        <box size="0.15 0.15 0.15"/>
      </geometry>
      <origin xyz="0 0 0" rpy="1.57 0 0"/>
      <material name="black"/>
      </visual>
        <sensor type="gpu_ray" name="head_hokuyo_sensor">
          <pose>1 0 0.025 0 0 0</pose>
          <visualize>true</visualize>
          <update_rate>40</update_rate>
          <ray>
            <scan>
              <horizontal>
                <samples>400</samples>
                <resolution>1</resolution>
                <min_angle>-1.570796</min_angle>
                <max_angle>1.570796</max_angle>
              </horizontal>
            </scan>
            <range>
              <min>0.1</min>
              <max>6</max>
              <resolution>0.01</resolution>
            </range>
          </ray>
          <plugin name="gazebo_ros_head_hokuyo_controller" filename="libgazebo_ros_laser.so">
            <topicName>/scan</topicName>
           </plugin>
        </sensor>
      </link>

	<joint name="laser_joint" type="fixed">
	    <parent link="base_link"/>
	    <child link="laser"/>
	    <origin xyz="1.2 0 0.25" rpy="0 0 0"/>
	  </joint-->
  <!--gazebo>
    <plugin name="ackermann_steering_controller" filename="libackermann_steering_controller.so">
      <rosDebugLevel>Debug</rosDebugLevel>
      <publishWheelTF>false</publishWheelTF>
      <publishTf>1</publishTf>
      <publishWheelJointState>false</publishWheelJointState>
      <alwaysOn>true</alwaysOn>
      <updateRate>100.0</updateRate>
      <fronSteer>front_steer_joint</frontSteer>
      <rearWheel>rear_wheel_joint</rearWheel>
      <broadcastTF>1</broadcastTF>
      <base_linkmandTopic>cmd_vel</base_linkmandTopic>
      <odometryFrame>odom</odometryFrame>
      <odometryTopic>odom</odometryTopic>
      <robotBaseFrame>base_link</robotBaseFrame>


    </plugin>
  </gazebo-->




</robot>
